JWTAuthWSMiddleware called
No token provided
Exception inside application: No route found for path 'ws/user/undefined'.
Traceback (most recent call last):
  File "/usr/local/lib/python3.12/site-packages/django/contrib/staticfiles/handlers.py", line 101, in __call__
    return await self.application(scope, receive, send)
           ^^^^^^^^^^^^^^^^^^^^^^^^^^^^^^^^^^^^^^^^^^^^
  File "/usr/local/lib/python3.12/site-packages/channels/routing.py", line 62, in __call__
    return await application(scope, receive, send)
           ^^^^^^^^^^^^^^^^^^^^^^^^^^^^^^^^^^^^^^^
  File "/home/Pong/web/userManagement/middleware.py", line 62, in __call__
    return await self.app(scope, receive, send)
           ^^^^^^^^^^^^^^^^^^^^^^^^^^^^^^^^^^^^
  File "/usr/local/lib/python3.12/site-packages/channels/sessions.py", line 47, in __call__
    return await self.inner(dict(scope, cookies=cookies), receive, send)
           ^^^^^^^^^^^^^^^^^^^^^^^^^^^^^^^^^^^^^^^^^^^^^^^^^^^^^^^^^^^^^
  File "/usr/local/lib/python3.12/site-packages/channels/sessions.py", line 263, in __call__
    return await self.inner(wrapper.scope, receive, wrapper.send)
           ^^^^^^^^^^^^^^^^^^^^^^^^^^^^^^^^^^^^^^^^^^^^^^^^^^^^^^
  File "/usr/local/lib/python3.12/site-packages/channels/auth.py", line 185, in __call__
    return await super().__call__(scope, receive, send)
           ^^^^^^^^^^^^^^^^^^^^^^^^^^^^^^^^^^^^^^^^^^^^
  File "/usr/local/lib/python3.12/site-packages/channels/middleware.py", line 24, in __call__
    return await self.inner(scope, receive, send)
           ^^^^^^^^^^^^^^^^^^^^^^^^^^^^^^^^^^^^^^
  File "/usr/local/lib/python3.12/site-packages/channels/routing.py", line 150, in __call__
    raise ValueError("No route found for path %r." % path)
ValueError: No route found for path 'ws/user/undefined'.
JWTAuthWSMiddleware called
No token provided
Exception inside application: No route found for path 'ws/user/undefined'.
Traceback (most recent call last):
  File "/usr/local/lib/python3.12/site-packages/django/contrib/staticfiles/handlers.py", line 101, in __call__
    return await self.application(scope, receive, send)
           ^^^^^^^^^^^^^^^^^^^^^^^^^^^^^^^^^^^^^^^^^^^^
  File "/usr/local/lib/python3.12/site-packages/channels/routing.py", line 62, in __call__
    return await application(scope, receive, send)
           ^^^^^^^^^^^^^^^^^^^^^^^^^^^^^^^^^^^^^^^
  File "/home/Pong/web/userManagement/middleware.py", line 62, in __call__
    return await self.app(scope, receive, send)
           ^^^^^^^^^^^^^^^^^^^^^^^^^^^^^^^^^^^^
  File "/usr/local/lib/python3.12/site-packages/channels/sessions.py", line 47, in __call__
    return await self.inner(dict(scope, cookies=cookies), receive, send)
           ^^^^^^^^^^^^^^^^^^^^^^^^^^^^^^^^^^^^^^^^^^^^^^^^^^^^^^^^^^^^^
  File "/usr/local/lib/python3.12/site-packages/channels/sessions.py", line 263, in __call__
    return await self.inner(wrapper.scope, receive, wrapper.send)
           ^^^^^^^^^^^^^^^^^^^^^^^^^^^^^^^^^^^^^^^^^^^^^^^^^^^^^^
  File "/usr/local/lib/python3.12/site-packages/channels/auth.py", line 185, in __call__
    return await super().__call__(scope, receive, send)
           ^^^^^^^^^^^^^^^^^^^^^^^^^^^^^^^^^^^^^^^^^^^^
  File "/usr/local/lib/python3.12/site-packages/channels/middleware.py", line 24, in __call__
    return await self.inner(scope, receive, send)
           ^^^^^^^^^^^^^^^^^^^^^^^^^^^^^^^^^^^^^^
  File "/usr/local/lib/python3.12/site-packages/channels/routing.py", line 150, in __call__
    raise ValueError("No route found for path %r." % path)
ValueError: No route found for path 'ws/user/undefined'.
JWTAuthWSMiddleware called
No token provided
Exception inside application: No route found for path 'ws/user/undefined'.
Traceback (most recent call last):
  File "/usr/local/lib/python3.12/site-packages/django/contrib/staticfiles/handlers.py", line 101, in __call__
    return await self.application(scope, receive, send)
           ^^^^^^^^^^^^^^^^^^^^^^^^^^^^^^^^^^^^^^^^^^^^
  File "/usr/local/lib/python3.12/site-packages/channels/routing.py", line 62, in __call__
    return await application(scope, receive, send)
           ^^^^^^^^^^^^^^^^^^^^^^^^^^^^^^^^^^^^^^^
  File "/home/Pong/web/userManagement/middleware.py", line 62, in __call__
    return await self.app(scope, receive, send)
           ^^^^^^^^^^^^^^^^^^^^^^^^^^^^^^^^^^^^
  File "/usr/local/lib/python3.12/site-packages/channels/sessions.py", line 47, in __call__
    return await self.inner(dict(scope, cookies=cookies), receive, send)
           ^^^^^^^^^^^^^^^^^^^^^^^^^^^^^^^^^^^^^^^^^^^^^^^^^^^^^^^^^^^^^
  File "/usr/local/lib/python3.12/site-packages/channels/sessions.py", line 263, in __call__
    return await self.inner(wrapper.scope, receive, wrapper.send)
           ^^^^^^^^^^^^^^^^^^^^^^^^^^^^^^^^^^^^^^^^^^^^^^^^^^^^^^
  File "/usr/local/lib/python3.12/site-packages/channels/auth.py", line 185, in __call__
    return await super().__call__(scope, receive, send)
           ^^^^^^^^^^^^^^^^^^^^^^^^^^^^^^^^^^^^^^^^^^^^
  File "/usr/local/lib/python3.12/site-packages/channels/middleware.py", line 24, in __call__
    return await self.inner(scope, receive, send)
           ^^^^^^^^^^^^^^^^^^^^^^^^^^^^^^^^^^^^^^
  File "/usr/local/lib/python3.12/site-packages/channels/routing.py", line 150, in __call__
    raise ValueError("No route found for path %r." % path)
ValueError: No route found for path 'ws/user/undefined'.
JWTAuthWSMiddleware called
No token provided
Exception inside application: No route found for path 'ws/user/undefined'.
Traceback (most recent call last):
  File "/usr/local/lib/python3.12/site-packages/django/contrib/staticfiles/handlers.py", line 101, in __call__
    return await self.application(scope, receive, send)
           ^^^^^^^^^^^^^^^^^^^^^^^^^^^^^^^^^^^^^^^^^^^^
  File "/usr/local/lib/python3.12/site-packages/channels/routing.py", line 62, in __call__
    return await application(scope, receive, send)
           ^^^^^^^^^^^^^^^^^^^^^^^^^^^^^^^^^^^^^^^
  File "/home/Pong/web/userManagement/middleware.py", line 62, in __call__
    return await self.app(scope, receive, send)
           ^^^^^^^^^^^^^^^^^^^^^^^^^^^^^^^^^^^^
  File "/usr/local/lib/python3.12/site-packages/channels/sessions.py", line 47, in __call__
    return await self.inner(dict(scope, cookies=cookies), receive, send)
           ^^^^^^^^^^^^^^^^^^^^^^^^^^^^^^^^^^^^^^^^^^^^^^^^^^^^^^^^^^^^^
  File "/usr/local/lib/python3.12/site-packages/channels/sessions.py", line 263, in __call__
    return await self.inner(wrapper.scope, receive, wrapper.send)
           ^^^^^^^^^^^^^^^^^^^^^^^^^^^^^^^^^^^^^^^^^^^^^^^^^^^^^^
  File "/usr/local/lib/python3.12/site-packages/channels/auth.py", line 185, in __call__
    return await super().__call__(scope, receive, send)
           ^^^^^^^^^^^^^^^^^^^^^^^^^^^^^^^^^^^^^^^^^^^^
  File "/usr/local/lib/python3.12/site-packages/channels/middleware.py", line 24, in __call__
    return await self.inner(scope, receive, send)
           ^^^^^^^^^^^^^^^^^^^^^^^^^^^^^^^^^^^^^^
  File "/usr/local/lib/python3.12/site-packages/channels/routing.py", line 150, in __call__
    raise ValueError("No route found for path %r." % path)
ValueError: No route found for path 'ws/user/undefined'.
JWTAuthWSMiddleware called
No token provided
Exception inside application: No route found for path 'ws/user/undefined'.
Traceback (most recent call last):
  File "/usr/local/lib/python3.12/site-packages/django/contrib/staticfiles/handlers.py", line 101, in __call__
    return await self.application(scope, receive, send)
           ^^^^^^^^^^^^^^^^^^^^^^^^^^^^^^^^^^^^^^^^^^^^
  File "/usr/local/lib/python3.12/site-packages/channels/routing.py", line 62, in __call__
    return await application(scope, receive, send)
           ^^^^^^^^^^^^^^^^^^^^^^^^^^^^^^^^^^^^^^^
  File "/home/Pong/web/userManagement/middleware.py", line 62, in __call__
    return await self.app(scope, receive, send)
           ^^^^^^^^^^^^^^^^^^^^^^^^^^^^^^^^^^^^
  File "/usr/local/lib/python3.12/site-packages/channels/sessions.py", line 47, in __call__
    return await self.inner(dict(scope, cookies=cookies), receive, send)
           ^^^^^^^^^^^^^^^^^^^^^^^^^^^^^^^^^^^^^^^^^^^^^^^^^^^^^^^^^^^^^
  File "/usr/local/lib/python3.12/site-packages/channels/sessions.py", line 263, in __call__
    return await self.inner(wrapper.scope, receive, wrapper.send)
           ^^^^^^^^^^^^^^^^^^^^^^^^^^^^^^^^^^^^^^^^^^^^^^^^^^^^^^
  File "/usr/local/lib/python3.12/site-packages/channels/auth.py", line 185, in __call__
    return await super().__call__(scope, receive, send)
           ^^^^^^^^^^^^^^^^^^^^^^^^^^^^^^^^^^^^^^^^^^^^
  File "/usr/local/lib/python3.12/site-packages/channels/middleware.py", line 24, in __call__
    return await self.inner(scope, receive, send)
           ^^^^^^^^^^^^^^^^^^^^^^^^^^^^^^^^^^^^^^
  File "/usr/local/lib/python3.12/site-packages/channels/routing.py", line 150, in __call__
    raise ValueError("No route found for path %r." % path)
ValueError: No route found for path 'ws/user/undefined'.
JWTAuthWSMiddleware called
No token provided
Exception inside application: No route found for path 'ws/user/eyJhbGciOiJIUzI1NiIsInR5cCI6IkpXVCJ9.eyJpZCI6MSwidXNlcm5hbWUiOiJzdXBlcnVzZXIiLCJleHAiOjE3MjE5MTQ2MzYsImlhdCI6MTcyMTkxNDUxNn0.lCJOcuGsB5ASqnUilQ7unoOPuSWESxGSh9nAXDSQlQI'.
Traceback (most recent call last):
  File "/usr/local/lib/python3.12/site-packages/django/contrib/staticfiles/handlers.py", line 101, in __call__
    return await self.application(scope, receive, send)
           ^^^^^^^^^^^^^^^^^^^^^^^^^^^^^^^^^^^^^^^^^^^^
  File "/usr/local/lib/python3.12/site-packages/channels/routing.py", line 62, in __call__
    return await application(scope, receive, send)
           ^^^^^^^^^^^^^^^^^^^^^^^^^^^^^^^^^^^^^^^
  File "/home/Pong/web/userManagement/middleware.py", line 62, in __call__
    return await self.app(scope, receive, send)
           ^^^^^^^^^^^^^^^^^^^^^^^^^^^^^^^^^^^^
  File "/usr/local/lib/python3.12/site-packages/channels/sessions.py", line 47, in __call__
    return await self.inner(dict(scope, cookies=cookies), receive, send)
           ^^^^^^^^^^^^^^^^^^^^^^^^^^^^^^^^^^^^^^^^^^^^^^^^^^^^^^^^^^^^^
  File "/usr/local/lib/python3.12/site-packages/channels/sessions.py", line 263, in __call__
    return await self.inner(wrapper.scope, receive, wrapper.send)
           ^^^^^^^^^^^^^^^^^^^^^^^^^^^^^^^^^^^^^^^^^^^^^^^^^^^^^^
  File "/usr/local/lib/python3.12/site-packages/channels/auth.py", line 185, in __call__
    return await super().__call__(scope, receive, send)
           ^^^^^^^^^^^^^^^^^^^^^^^^^^^^^^^^^^^^^^^^^^^^
  File "/usr/local/lib/python3.12/site-packages/channels/middleware.py", line 24, in __call__
    return await self.inner(scope, receive, send)
           ^^^^^^^^^^^^^^^^^^^^^^^^^^^^^^^^^^^^^^
  File "/usr/local/lib/python3.12/site-packages/channels/routing.py", line 150, in __call__
    raise ValueError("No route found for path %r." % path)
ValueError: No route found for path 'ws/user/eyJhbGciOiJIUzI1NiIsInR5cCI6IkpXVCJ9.eyJpZCI6MSwidXNlcm5hbWUiOiJzdXBlcnVzZXIiLCJleHAiOjE3MjE5MTQ2MzYsImlhdCI6MTcyMTkxNDUxNn0.lCJOcuGsB5ASqnUilQ7unoOPuSWESxGSh9nAXDSQlQI'.

------------------------------


Unauthorized: /login
HTTP POST /login 401 [0.15, 172.18.0.4:46992]
JWTAuthWSMiddleware called
user id: None
Authenticated user: 

--------------

JWTAuthWSMiddleware called
user id: 1
Authenticated user: superuser
JWTAuthWSMiddleware called
user id: 1
Authenticated user: superuser
JWTAuthWSMiddleware called
user id: 1
Authenticated user: superuser
