JWTAuthWSMiddleware called
Authenticated user: superuser
Exception inside application: Error -3 connecting to redis:6379. -3.
Traceback (most recent call last):
  File "/usr/local/lib/python3.12/site-packages/redis/asyncio/connection.py", line 274, in connect
    await self.retry.call_with_retry(
  File "/usr/local/lib/python3.12/site-packages/redis/asyncio/retry.py", line 59, in call_with_retry
    return await do()
           ^^^^^^^^^^
  File "/usr/local/lib/python3.12/site-packages/redis/asyncio/connection.py", line 681, in _connect
    reader, writer = await asyncio.open_connection(
                     ^^^^^^^^^^^^^^^^^^^^^^^^^^^^^^
  File "/usr/local/lib/python3.12/asyncio/streams.py", line 48, in open_connection
    transport, _ = await loop.create_connection(
                   ^^^^^^^^^^^^^^^^^^^^^^^^^^^^^
  File "/usr/local/lib/python3.12/asyncio/base_events.py", line 1080, in create_connection
    infos = await self._ensure_resolved(
            ^^^^^^^^^^^^^^^^^^^^^^^^^^^^
  File "/usr/local/lib/python3.12/asyncio/base_events.py", line 1456, in _ensure_resolved
    return await loop.getaddrinfo(host, port, family=family, type=type,
           ^^^^^^^^^^^^^^^^^^^^^^^^^^^^^^^^^^^^^^^^^^^^^^^^^^^^^^^^^^^^
  File "/usr/local/lib/python3.12/asyncio/base_events.py", line 901, in getaddrinfo
    return await self.run_in_executor(
           ^^^^^^^^^^^^^^^^^^^^^^^^^^^
  File "/usr/local/lib/python3.12/concurrent/futures/thread.py", line 58, in run
    result = self.fn(*self.args, **self.kwargs)
             ^^^^^^^^^^^^^^^^^^^^^^^^^^^^^^^^^^
  File "/usr/local/lib/python3.12/socket.py", line 964, in getaddrinfo
    for res in _socket.getaddrinfo(host, port, family, type, proto, flags):
               ^^^^^^^^^^^^^^^^^^^^^^^^^^^^^^^^^^^^^^^^^^^^^^^^^^^^^^^^^^^
socket.gaierror: [Errno -3] Temporary failure in name resolution

During handling of the above exception, another exception occurred:

Traceback (most recent call last):
  File "/usr/local/lib/python3.12/site-packages/django/contrib/staticfiles/handlers.py", line 101, in __call__
    return await self.application(scope, receive, send)
           ^^^^^^^^^^^^^^^^^^^^^^^^^^^^^^^^^^^^^^^^^^^^
  File "/usr/local/lib/python3.12/site-packages/channels/routing.py", line 62, in __call__
    return await application(scope, receive, send)
           ^^^^^^^^^^^^^^^^^^^^^^^^^^^^^^^^^^^^^^^
  File "/home/Pong/web/userManagement/middleware.py", line 62, in __call__
    return await self.app(scope, receive, send)
           ^^^^^^^^^^^^^^^^^^^^^^^^^^^^^^^^^^^^
  File "/usr/local/lib/python3.12/site-packages/channels/routing.py", line 132, in __call__
    return await application(
           ^^^^^^^^^^^^^^^^^^
  File "/usr/local/lib/python3.12/site-packages/channels/consumer.py", line 94, in app
    return await consumer(scope, receive, send)
           ^^^^^^^^^^^^^^^^^^^^^^^^^^^^^^^^^^^^
  File "/usr/local/lib/python3.12/site-packages/channels/consumer.py", line 58, in __call__
    await await_many_dispatch(
  File "/usr/local/lib/python3.12/site-packages/channels/utils.py", line 57, in await_many_dispatch
    await task
redis.exceptions.ConnectionError: Error -3 connecting to redis:6379. -3.
JWTAuthWSMiddleware called
Authenticated user: superuser


----


